2024-06-13 17:27:16 ERROR 400 response executing GraphQL.
2024-06-13 17:27:16 ERROR {"errors":[{"message":"name required for project query","path":["project"]}],"data":{"project":null}}
2024-06-13 17:27:16 ERROR Traceback (most recent call last):
  File "/home/foottracker/.local/lib/python3.8/site-packages/wandb/apis/normalize.py", line 41, in wrapper
    return func(*args, **kwargs)
  File "/home/foottracker/.local/lib/python3.8/site-packages/wandb/sdk/internal/internal_api.py", line 1026, in sweep
    response = self.gql(
  File "/home/foottracker/.local/lib/python3.8/site-packages/wandb/sdk/internal/internal_api.py", line 312, in gql
    ret = self._retry_gql(
  File "/home/foottracker/.local/lib/python3.8/site-packages/wandb/sdk/lib/retry.py", line 131, in __call__
    result = self._call_fn(*args, **kwargs)
  File "/home/foottracker/.local/lib/python3.8/site-packages/wandb/sdk/internal/internal_api.py", line 340, in execute
    return self.client.execute(*args, **kwargs)  # type: ignore
  File "/home/foottracker/.local/lib/python3.8/site-packages/wandb/vendor/gql-0.2.0/wandb_gql/client.py", line 52, in execute
    result = self._get_result(document, *args, **kwargs)
  File "/home/foottracker/.local/lib/python3.8/site-packages/wandb/vendor/gql-0.2.0/wandb_gql/client.py", line 60, in _get_result
    return self.transport.execute(document, *args, **kwargs)
  File "/home/foottracker/.local/lib/python3.8/site-packages/wandb/sdk/lib/gql_request.py", line 59, in execute
    request.raise_for_status()
  File "/home/foottracker/.local/lib/python3.8/site-packages/requests/models.py", line 1021, in raise_for_status
    raise HTTPError(http_error_msg, response=self)
requests.exceptions.HTTPError: 400 Client Error: Bad Request for url: https://api.wandb.ai/graphql

During handling of the above exception, another exception occurred:

Traceback (most recent call last):
  File "/home/foottracker/.local/lib/python3.8/site-packages/wandb/cli/cli.py", line 108, in wrapper
    return func(*args, **kwargs)
  File "/home/foottracker/.local/lib/python3.8/site-packages/wandb/cli/cli.py", line 1806, in agent
    wandb_agent.agent(sweep_id, entity=entity, project=project, count=count)
  File "/home/foottracker/.local/lib/python3.8/site-packages/wandb/wandb_agent.py", line 570, in agent
    return run_agent(
  File "/home/foottracker/.local/lib/python3.8/site-packages/wandb/wandb_agent.py", line 528, in run_agent
    agent.run()
  File "/home/foottracker/.local/lib/python3.8/site-packages/wandb/wandb_agent.py", line 190, in run
    sweep_obj = self._api.sweep(self._sweep_id, "{}")
  File "/home/foottracker/.local/lib/python3.8/site-packages/wandb/apis/internal.py", line 126, in sweep
    return self.api.sweep(*args, **kwargs)
  File "/home/foottracker/.local/lib/python3.8/site-packages/wandb/apis/normalize.py", line 51, in wrapper
    raise CommError(message, error)
wandb.errors.CommError: name required for project query (Error 400: Bad Request)

2024-06-13 17:29:00 ERROR 400 response executing GraphQL.
2024-06-13 17:29:00 ERROR {"errors":[{"message":"name required for project query","path":["project"]}],"data":{"project":null}}
2024-06-13 17:29:00 ERROR Traceback (most recent call last):
  File "/home/foottracker/.local/lib/python3.8/site-packages/wandb/apis/normalize.py", line 41, in wrapper
    return func(*args, **kwargs)
  File "/home/foottracker/.local/lib/python3.8/site-packages/wandb/sdk/internal/internal_api.py", line 1026, in sweep
    response = self.gql(
  File "/home/foottracker/.local/lib/python3.8/site-packages/wandb/sdk/internal/internal_api.py", line 312, in gql
    ret = self._retry_gql(
  File "/home/foottracker/.local/lib/python3.8/site-packages/wandb/sdk/lib/retry.py", line 131, in __call__
    result = self._call_fn(*args, **kwargs)
  File "/home/foottracker/.local/lib/python3.8/site-packages/wandb/sdk/internal/internal_api.py", line 340, in execute
    return self.client.execute(*args, **kwargs)  # type: ignore
  File "/home/foottracker/.local/lib/python3.8/site-packages/wandb/vendor/gql-0.2.0/wandb_gql/client.py", line 52, in execute
    result = self._get_result(document, *args, **kwargs)
  File "/home/foottracker/.local/lib/python3.8/site-packages/wandb/vendor/gql-0.2.0/wandb_gql/client.py", line 60, in _get_result
    return self.transport.execute(document, *args, **kwargs)
  File "/home/foottracker/.local/lib/python3.8/site-packages/wandb/sdk/lib/gql_request.py", line 59, in execute
    request.raise_for_status()
  File "/home/foottracker/.local/lib/python3.8/site-packages/requests/models.py", line 1021, in raise_for_status
    raise HTTPError(http_error_msg, response=self)
requests.exceptions.HTTPError: 400 Client Error: Bad Request for url: https://api.wandb.ai/graphql

During handling of the above exception, another exception occurred:

Traceback (most recent call last):
  File "/home/foottracker/.local/lib/python3.8/site-packages/wandb/cli/cli.py", line 108, in wrapper
    return func(*args, **kwargs)
  File "/home/foottracker/.local/lib/python3.8/site-packages/wandb/cli/cli.py", line 1806, in agent
    wandb_agent.agent(sweep_id, entity=entity, project=project, count=count)
  File "/home/foottracker/.local/lib/python3.8/site-packages/wandb/wandb_agent.py", line 570, in agent
    return run_agent(
  File "/home/foottracker/.local/lib/python3.8/site-packages/wandb/wandb_agent.py", line 528, in run_agent
    agent.run()
  File "/home/foottracker/.local/lib/python3.8/site-packages/wandb/wandb_agent.py", line 190, in run
    sweep_obj = self._api.sweep(self._sweep_id, "{}")
  File "/home/foottracker/.local/lib/python3.8/site-packages/wandb/apis/internal.py", line 126, in sweep
    return self.api.sweep(*args, **kwargs)
  File "/home/foottracker/.local/lib/python3.8/site-packages/wandb/apis/normalize.py", line 51, in wrapper
    raise CommError(message, error)
wandb.errors.CommError: name required for project query (Error 400: Bad Request)

2024-06-13 19:19:30 ERROR 400 response executing GraphQL.
2024-06-13 19:19:30 ERROR {"errors":[{"message":"entityName required for project query","path":["project"]}],"data":{"project":null}}
2024-06-13 19:19:30 ERROR Traceback (most recent call last):
  File "/home/foottracker/myenv/lib/python3.8/site-packages/wandb/apis/normalize.py", line 41, in wrapper
    return func(*args, **kwargs)
  File "/home/foottracker/myenv/lib/python3.8/site-packages/wandb/sdk/internal/internal_api.py", line 1026, in sweep
    response = self.gql(
  File "/home/foottracker/myenv/lib/python3.8/site-packages/wandb/sdk/internal/internal_api.py", line 312, in gql
    ret = self._retry_gql(
  File "/home/foottracker/myenv/lib/python3.8/site-packages/wandb/sdk/lib/retry.py", line 131, in __call__
    result = self._call_fn(*args, **kwargs)
  File "/home/foottracker/myenv/lib/python3.8/site-packages/wandb/sdk/internal/internal_api.py", line 340, in execute
    return self.client.execute(*args, **kwargs)  # type: ignore
  File "/home/foottracker/myenv/lib/python3.8/site-packages/wandb/vendor/gql-0.2.0/wandb_gql/client.py", line 52, in execute
    result = self._get_result(document, *args, **kwargs)
  File "/home/foottracker/myenv/lib/python3.8/site-packages/wandb/vendor/gql-0.2.0/wandb_gql/client.py", line 60, in _get_result
    return self.transport.execute(document, *args, **kwargs)
  File "/home/foottracker/myenv/lib/python3.8/site-packages/wandb/sdk/lib/gql_request.py", line 59, in execute
    request.raise_for_status()
  File "/home/foottracker/myenv/lib/python3.8/site-packages/requests/models.py", line 1021, in raise_for_status
    raise HTTPError(http_error_msg, response=self)
requests.exceptions.HTTPError: 400 Client Error: Bad Request for url: https://api.wandb.ai/graphql

During handling of the above exception, another exception occurred:

Traceback (most recent call last):
  File "/home/foottracker/myenv/lib/python3.8/site-packages/wandb/cli/cli.py", line 108, in wrapper
    return func(*args, **kwargs)
  File "/home/foottracker/myenv/lib/python3.8/site-packages/wandb/cli/cli.py", line 1806, in agent
    wandb_agent.agent(sweep_id, entity=entity, project=project, count=count)
  File "/home/foottracker/myenv/lib/python3.8/site-packages/wandb/wandb_agent.py", line 570, in agent
    return run_agent(
  File "/home/foottracker/myenv/lib/python3.8/site-packages/wandb/wandb_agent.py", line 528, in run_agent
    agent.run()
  File "/home/foottracker/myenv/lib/python3.8/site-packages/wandb/wandb_agent.py", line 190, in run
    sweep_obj = self._api.sweep(self._sweep_id, "{}")
  File "/home/foottracker/myenv/lib/python3.8/site-packages/wandb/apis/internal.py", line 126, in sweep
    return self.api.sweep(*args, **kwargs)
  File "/home/foottracker/myenv/lib/python3.8/site-packages/wandb/apis/normalize.py", line 51, in wrapper
    raise CommError(message, error)
wandb.errors.CommError: entityName required for project query (Error 400: Bad Request)

2024-06-13 19:31:27 ERROR 400 response executing GraphQL.
2024-06-13 19:31:27 ERROR {"errors":[{"message":"entityName required for project query","path":["project"]}],"data":{"project":null}}
2024-06-13 19:31:27 ERROR Traceback (most recent call last):
  File "/home/foottracker/myenv/lib/python3.8/site-packages/wandb/apis/normalize.py", line 41, in wrapper
    return func(*args, **kwargs)
  File "/home/foottracker/myenv/lib/python3.8/site-packages/wandb/sdk/internal/internal_api.py", line 1026, in sweep
    response = self.gql(
  File "/home/foottracker/myenv/lib/python3.8/site-packages/wandb/sdk/internal/internal_api.py", line 312, in gql
    ret = self._retry_gql(
  File "/home/foottracker/myenv/lib/python3.8/site-packages/wandb/sdk/lib/retry.py", line 131, in __call__
    result = self._call_fn(*args, **kwargs)
  File "/home/foottracker/myenv/lib/python3.8/site-packages/wandb/sdk/internal/internal_api.py", line 340, in execute
    return self.client.execute(*args, **kwargs)  # type: ignore
  File "/home/foottracker/myenv/lib/python3.8/site-packages/wandb/vendor/gql-0.2.0/wandb_gql/client.py", line 52, in execute
    result = self._get_result(document, *args, **kwargs)
  File "/home/foottracker/myenv/lib/python3.8/site-packages/wandb/vendor/gql-0.2.0/wandb_gql/client.py", line 60, in _get_result
    return self.transport.execute(document, *args, **kwargs)
  File "/home/foottracker/myenv/lib/python3.8/site-packages/wandb/sdk/lib/gql_request.py", line 59, in execute
    request.raise_for_status()
  File "/home/foottracker/myenv/lib/python3.8/site-packages/requests/models.py", line 1021, in raise_for_status
    raise HTTPError(http_error_msg, response=self)
requests.exceptions.HTTPError: 400 Client Error: Bad Request for url: https://api.wandb.ai/graphql

During handling of the above exception, another exception occurred:

Traceback (most recent call last):
  File "/home/foottracker/myenv/lib/python3.8/site-packages/wandb/cli/cli.py", line 108, in wrapper
    return func(*args, **kwargs)
  File "/home/foottracker/myenv/lib/python3.8/site-packages/wandb/cli/cli.py", line 1806, in agent
    wandb_agent.agent(sweep_id, entity=entity, project=project, count=count)
  File "/home/foottracker/myenv/lib/python3.8/site-packages/wandb/wandb_agent.py", line 570, in agent
    return run_agent(
  File "/home/foottracker/myenv/lib/python3.8/site-packages/wandb/wandb_agent.py", line 528, in run_agent
    agent.run()
  File "/home/foottracker/myenv/lib/python3.8/site-packages/wandb/wandb_agent.py", line 190, in run
    sweep_obj = self._api.sweep(self._sweep_id, "{}")
  File "/home/foottracker/myenv/lib/python3.8/site-packages/wandb/apis/internal.py", line 126, in sweep
    return self.api.sweep(*args, **kwargs)
  File "/home/foottracker/myenv/lib/python3.8/site-packages/wandb/apis/normalize.py", line 51, in wrapper
    raise CommError(message, error)
wandb.errors.CommError: entityName required for project query (Error 400: Bad Request)

