
Epoch 1, Batch 10, Loss: 0.0002, Accuracy: 28.12%
Epoch 1, Batch 20, Loss: 0.0001, Accuracy: 28.12%
Epoch 1, Batch 30, Loss: 0.0001, Accuracy: 32.71%
Epoch 1, Batch 40, Loss: 0.0000, Accuracy: 36.88%
Epoch 2, Batch 10, Loss: 0.0000, Accuracy: 55.62%
Epoch 2, Batch 20, Loss: 0.0000, Accuracy: 56.56%
ok
[34m[1mwandb[39m[22m: Ctrl + C detected. Stopping sweep.
Traceback (most recent call last):
  File "/home/foottracker/myenv/lib/python3.8/site-packages/torch/utils/data/dataloader.py", line 1120, in _try_get_data
    data = self._data_queue.get(timeout=timeout)
  File "/usr/lib/python3.8/multiprocessing/queues.py", line 107, in get
    if not self._poll(timeout):
  File "/usr/lib/python3.8/multiprocessing/connection.py", line 257, in poll
    return self._poll(timeout)
  File "/usr/lib/python3.8/multiprocessing/connection.py", line 424, in _poll
    r = wait([self], timeout)
  File "/usr/lib/python3.8/multiprocessing/connection.py", line 931, in wait
    ready = selector.select(timeout)
  File "/usr/lib/python3.8/selectors.py", line 415, in select
    fd_event_list = self._selector.poll(timeout)
Exception
The above exception was the direct cause of the following exception:
Traceback (most recent call last):
  File "/home/foottracker/myenv/FootTracker/Detection/last.py", line 208, in train_model
  File "/home/foottracker/myenv/lib/python3.8/site-packages/torch/utils/data/dataloader.py", line 628, in __next__
    data = self._next_data()
  File "/home/foottracker/myenv/lib/python3.8/site-packages/torch/utils/data/dataloader.py", line 1316, in _next_data
    idx, data = self._get_data()
  File "/home/foottracker/myenv/lib/python3.8/site-packages/torch/utils/data/dataloader.py", line 1282, in _get_data
    success, data = self._try_get_data()
  File "/home/foottracker/myenv/lib/python3.8/site-packages/torch/utils/data/dataloader.py", line 1133, in _try_get_data
    raise RuntimeError('DataLoader worker (pid(s) {}) exited unexpectedly'.format(pids_str)) from e
RuntimeError: DataLoader worker (pid(s) 803428, 803568, 803642) exited unexpectedly