Traceback (most recent call last):
  File "/usr/lib/python3.8/runpy.py", line 194, in _run_module_as_main
    return _run_code(code, main_globals, None,
  File "/usr/lib/python3.8/runpy.py", line 87, in _run_code
    exec(code, run_globals)
  File "/home/foottracker/.vscode-server/extensions/ms-python.debugpy-2024.6.0-linux-x64/bundled/libs/debugpy/adapter/../../debugpy/launcher/../../debugpy/__main__.py", line 39, in <module>
    cli.main()
  File "/home/foottracker/.vscode-server/extensions/ms-python.debugpy-2024.6.0-linux-x64/bundled/libs/debugpy/adapter/../../debugpy/launcher/../../debugpy/../debugpy/server/cli.py", line 430, in main
    run()
  File "/home/foottracker/.vscode-server/extensions/ms-python.debugpy-2024.6.0-linux-x64/bundled/libs/debugpy/adapter/../../debugpy/launcher/../../debugpy/../debugpy/server/cli.py", line 284, in run_file
    runpy.run_path(target, run_name="__main__")
  File "/home/foottracker/.vscode-server/extensions/ms-python.debugpy-2024.6.0-linux-x64/bundled/libs/debugpy/_vendored/pydevd/_pydevd_bundle/pydevd_runpy.py", line 321, in run_path
    return _run_module_code(code, init_globals, run_name,
  File "/home/foottracker/.vscode-server/extensions/ms-python.debugpy-2024.6.0-linux-x64/bundled/libs/debugpy/_vendored/pydevd/_pydevd_bundle/pydevd_runpy.py", line 135, in _run_module_code
    _run_code(code, mod_globals, init_globals,
  File "/home/foottracker/.vscode-server/extensions/ms-python.debugpy-2024.6.0-linux-x64/bundled/libs/debugpy/_vendored/pydevd/_pydevd_bundle/pydevd_runpy.py", line 124, in _run_code
    exec(code, run_globals)
  File "/home/foottracker/myenv/FootTracker/Detection/c2.py", line 261, in <module>
    loss_history = train_model(model, train_loader, criterion, optimizer, num_epochs=10)
  File "/home/foottracker/myenv/FootTracker/Detection/c2.py", line 186, in train_model
    for batch_idx, (inputs, labels) in enumerate(train_loader):
  File "/home/foottracker/myenv/lib/python3.8/site-packages/torch/utils/data/dataloader.py", line 628, in __next__
    data = self._next_data()
  File "/home/foottracker/myenv/lib/python3.8/site-packages/torch/utils/data/dataloader.py", line 1333, in _next_data
    return self._process_data(data)
  File "/home/foottracker/myenv/lib/python3.8/site-packages/torch/utils/data/dataloader.py", line 1359, in _process_data
    data.reraise()
  File "/home/foottracker/myenv/lib/python3.8/site-packages/torch/_utils.py", line 543, in reraise
    raise exception
TypeError: Caught TypeError in DataLoader worker process 0.
Original Traceback (most recent call last):
  File "/home/foottracker/myenv/lib/python3.8/site-packages/torch/utils/data/_utils/worker.py", line 302, in _worker_loop
    data = fetcher.fetch(index)
  File "/home/foottracker/myenv/lib/python3.8/site-packages/torch/utils/data/_utils/fetch.py", line 58, in fetch
    data = [self.dataset[idx] for idx in possibly_batched_index]
  File "/home/foottracker/myenv/lib/python3.8/site-packages/torch/utils/data/_utils/fetch.py", line 58, in <listcomp>
    data = [self.dataset[idx] for idx in possibly_batched_index]
  File "/home/foottracker/myenv/FootTracker/Detection/c2.py", line 68, in __getitem__
    frame_path = os.path.join(batch_path, f'frame{i:03}.png')
  File "/usr/lib/python3.8/posixpath.py", line 76, in join
    a = os.fspath(a)
TypeError: expected str, bytes or os.PathLike object, not list