[34m[1mwandb[39m[22m: [33mWARNING[39m Calling wandb.login() after wandb.init() has no effect.
[34m[1mwandb[39m[22m: [32m[41mERROR[39m[49m Error while calling W&B API: could not find project foottracker/uncategorized during createAgent (<Response [404]>)
[34m[1mwandb[39m[22m: [32m[41mERROR[39m[49m could not find project foottracker/uncategorized during createAgent
Traceback (most recent call last):
  File "/home/foottracker/myenv/lib/python3.8/site-packages/wandb/sdk/lib/retry.py", line 131, in __call__
    result = self._call_fn(*args, **kwargs)
  File "/home/foottracker/myenv/lib/python3.8/site-packages/wandb/sdk/internal/internal_api.py", line 340, in execute
    return self.client.execute(*args, **kwargs)  # type: ignore
  File "/home/foottracker/myenv/lib/python3.8/site-packages/wandb/vendor/gql-0.2.0/wandb_gql/client.py", line 52, in execute
    result = self._get_result(document, *args, **kwargs)
  File "/home/foottracker/myenv/lib/python3.8/site-packages/wandb/vendor/gql-0.2.0/wandb_gql/client.py", line 60, in _get_result
    return self.transport.execute(document, *args, **kwargs)
  File "/home/foottracker/myenv/lib/python3.8/site-packages/wandb/sdk/lib/gql_request.py", line 59, in execute
    request.raise_for_status()
  File "/home/foottracker/myenv/lib/python3.8/site-packages/requests/models.py", line 1021, in raise_for_status
    raise HTTPError(http_error_msg, response=self)
requests.exceptions.HTTPError: 404 Client Error: Not Found for url: https://api.wandb.ai/graphql
During handling of the above exception, another exception occurred:
Traceback (most recent call last):
  File "sweep-grid.py", line 231, in <module>
    wandb.agent('3dbqyqit', function=train_model)
  File "/home/foottracker/myenv/lib/python3.8/site-packages/wandb/wandb_agent.py", line 568, in agent
    return pyagent(sweep_id, function, entity, project, count)
  File "/home/foottracker/myenv/lib/python3.8/site-packages/wandb/agents/pyagent.py", line 357, in pyagent
    agent.run()
  File "/home/foottracker/myenv/lib/python3.8/site-packages/wandb/agents/pyagent.py", line 328, in run
    self._setup()
  File "/home/foottracker/myenv/lib/python3.8/site-packages/wandb/agents/pyagent.py", line 136, in _setup
    self._register()
  File "/home/foottracker/myenv/lib/python3.8/site-packages/wandb/agents/pyagent.py", line 113, in _register
    agent = self._api.register_agent(socket.gethostname(), sweep_id=self._sweep_id)
  File "/home/foottracker/myenv/lib/python3.8/site-packages/wandb/apis/internal.py", line 150, in register_agent
    return self.api.register_agent(*args, **kwargs)
  File "/home/foottracker/myenv/lib/python3.8/site-packages/wandb/apis/normalize.py", line 73, in wrapper
    raise err
  File "/home/foottracker/myenv/lib/python3.8/site-packages/wandb/apis/normalize.py", line 41, in wrapper
    return func(*args, **kwargs)
  File "/home/foottracker/myenv/lib/python3.8/site-packages/wandb/sdk/internal/internal_api.py", line 2917, in register_agent
    response = self.gql(
  File "/home/foottracker/myenv/lib/python3.8/site-packages/wandb/sdk/internal/internal_api.py", line 312, in gql
    ret = self._retry_gql(
  File "/home/foottracker/myenv/lib/python3.8/site-packages/wandb/sdk/lib/retry.py", line 147, in __call__
    retry_timedelta_triggered = check_retry_fn(e)
  File "/home/foottracker/myenv/lib/python3.8/site-packages/wandb/util.py", line 878, in no_retry_4xx
    raise UsageError(body["errors"][0]["message"])
wandb.errors.UsageError: could not find project foottracker/uncategorized during createAgent