
Epoch 1, Batch 10, Loss: 0.1247, Accuracy: 79.06%
Epoch 1, Batch 20, Loss: 0.1215, Accuracy: 80.47%
Epoch 2, Batch 10, Loss: 0.1103, Accuracy: 82.19%
Epoch 2, Batch 20, Loss: 0.0877, Accuracy: 84.38%
Epoch 3, Batch 10, Loss: 0.1035, Accuracy: 84.06%
Epoch 3, Batch 20, Loss: 0.0963, Accuracy: 84.06%
Epoch 4, Batch 10, Loss: 0.0978, Accuracy: 81.88%
Epoch 4, Batch 20, Loss: 0.1019, Accuracy: 83.75%
Epoch 5, Batch 10, Loss: 0.1101, Accuracy: 82.81%
Epoch 5, Batch 20, Loss: 0.0942, Accuracy: 84.53%
 Processing...
[34m[1mwandb[39m[22m: Ctrl + C detected. Stopping sweep.
Traceback (most recent call last):
  File "/home/foottracker/myenv/lib/python3.8/site-packages/torch/utils/data/dataloader.py", line 1120, in _try_get_data
    data = self._data_queue.get(timeout=timeout)
  File "/usr/lib/python3.8/multiprocessing/queues.py", line 107, in get
    if not self._poll(timeout):
  File "/usr/lib/python3.8/multiprocessing/connection.py", line 257, in poll
    return self._poll(timeout)
  File "/usr/lib/python3.8/multiprocessing/connection.py", line 424, in _poll
    r = wait([self], timeout)
  File "/usr/lib/python3.8/multiprocessing/connection.py", line 931, in wait
    ready = selector.select(timeout)
  File "/usr/lib/python3.8/selectors.py", line 415, in select
    fd_event_list = self._selector.poll(timeout)
Exception
The above exception was the direct cause of the following exception:
Traceback (most recent call last):
  File "alpha.py", line 191, in train_model
    for batch_idx, (inputs, labels) in enumerate(train_loader):
  File "/home/foottracker/myenv/lib/python3.8/site-packages/torch/utils/data/dataloader.py", line 628, in __next__
    data = self._next_data()
  File "/home/foottracker/myenv/lib/python3.8/site-packages/torch/utils/data/dataloader.py", line 1316, in _next_data
    idx, data = self._get_data()
  File "/home/foottracker/myenv/lib/python3.8/site-packages/torch/utils/data/dataloader.py", line 1282, in _get_data
    success, data = self._try_get_data()
  File "/home/foottracker/myenv/lib/python3.8/site-packages/torch/utils/data/dataloader.py", line 1133, in _try_get_data
    raise RuntimeError('DataLoader worker (pid(s) {}) exited unexpectedly'.format(pids_str)) from e
RuntimeError: DataLoader worker (pid(s) 2975633, 2975701, 2975773) exited unexpectedly